2021-06-24 14:49:22,046 -- [run_tests.py-->line:10] - INFO: 开始执行测试用例......
2021-06-24 14:49:29,841 -- [run_tests.py-->line:26] - INFO: 测试用例执行完毕！
2021-07-01 16:24:05,596 -- [test_recharge_new.py-->line:76] - ERROR: 用例---会员id为字符串---执行未通过
2021-07-01 16:24:05,729 -- [test_recharge_new.py-->line:77] - DEBUG: 预期结果：{'code': 2, 'msg': '数字格式化异常'}
2021-07-01 16:24:05,729 -- [test_recharge_new.py-->line:78] - DEBUG: 实际结果：{'code': 0, 'msg': 'OK', 'data': {'id': 1362, 'leave_amount': 502400.32, 'mobile_phone': '15538098212', 'reg_name': '柚柚7', 'reg_time': '2021-07-01 16:23:11.0', 'type': 1}, 'copyright': 'Copyright 柠檬班 © 2017-2020 湖南省零檬信息技术有限公司 All Rights Reserved'}
2021-07-01 16:24:05,731 -- [test_recharge_new.py-->line:79] - ERROR:  :: 2 != 0
Traceback (most recent call last):
  File "D:\Program Files\JetBrains\PyCharm Community Edition 2020.2\plugins\python-ce\helpers\pycharm\teamcity\diff_tools.py", line 32, in _patched_equals
    old(self, first, second, msg)
  File "D:\Program Files\Python\Python38-32\lib\unittest\case.py", line 912, in assertEqual
    assertion_func(first, second, msg=msg)
  File "D:\Program Files\Python\Python38-32\lib\unittest\case.py", line 905, in _baseAssertEqual
    raise self.failureException(msg)
AssertionError: 2 != 0

During handling of the above exception, another exception occurred:

Traceback (most recent call last):
  File "D:\python\pythonProject\api_testing\testcases\test_recharge_new.py", line 68, in test_recharge
    self.assertEqual(expected['code'], res['code'])
  File "D:\Program Files\JetBrains\PyCharm Community Edition 2020.2\plugins\python-ce\helpers\pycharm\teamcity\diff_tools.py", line 38, in _patched_equals
    raise error
teamcity.diff_tools.EqualsAssertionError:  :: 2 != 0
2021-07-01 16:24:07,392 -- [test_recharge_new.py-->line:76] - ERROR: 用例---充值金额为0---执行未通过
2021-07-01 16:24:07,393 -- [test_recharge_new.py-->line:77] - DEBUG: 预期结果：{'code': 2, 'msg': '金额必须大于0并且小于或者等于500000'}
2021-07-01 16:24:07,393 -- [test_recharge_new.py-->line:78] - DEBUG: 实际结果：{'code': 0, 'msg': 'OK', 'data': {'id': 1362, 'leave_amount': 502400.32, 'mobile_phone': '15538098212', 'reg_name': '柚柚7', 'reg_time': '2021-07-01 16:23:11.0', 'type': 1}, 'copyright': 'Copyright 柠檬班 © 2017-2020 湖南省零檬信息技术有限公司 All Rights Reserved'}
2021-07-01 16:24:07,394 -- [test_recharge_new.py-->line:79] - ERROR:  :: 2 != 0
Traceback (most recent call last):
  File "D:\Program Files\JetBrains\PyCharm Community Edition 2020.2\plugins\python-ce\helpers\pycharm\teamcity\diff_tools.py", line 32, in _patched_equals
    old(self, first, second, msg)
  File "D:\Program Files\Python\Python38-32\lib\unittest\case.py", line 912, in assertEqual
    assertion_func(first, second, msg=msg)
  File "D:\Program Files\Python\Python38-32\lib\unittest\case.py", line 905, in _baseAssertEqual
    raise self.failureException(msg)
AssertionError: 2 != 0

During handling of the above exception, another exception occurred:

Traceback (most recent call last):
  File "D:\python\pythonProject\api_testing\testcases\test_recharge_new.py", line 68, in test_recharge
    self.assertEqual(expected['code'], res['code'])
  File "D:\Program Files\JetBrains\PyCharm Community Edition 2020.2\plugins\python-ce\helpers\pycharm\teamcity\diff_tools.py", line 38, in _patched_equals
    raise error
teamcity.diff_tools.EqualsAssertionError:  :: 2 != 0
2021-07-01 16:24:08,832 -- [test_recharge_new.py-->line:76] - ERROR: 用例---充值金额为空---执行未通过
2021-07-01 16:24:08,923 -- [test_recharge_new.py-->line:77] - DEBUG: 预期结果：{'code': 1, 'msg': '充值金额为空'}
2021-07-01 16:24:08,924 -- [test_recharge_new.py-->line:78] - DEBUG: 实际结果：{'code': 2, 'msg': '余额必须为数值型', 'data': None, 'copyright': 'Copyright 柠檬班 © 2017-2020 湖南省零檬信息技术有限公司 All Rights Reserved'}
2021-07-01 16:24:08,946 -- [test_recharge_new.py-->line:79] - ERROR:  :: 1 != 2
Traceback (most recent call last):
  File "D:\Program Files\JetBrains\PyCharm Community Edition 2020.2\plugins\python-ce\helpers\pycharm\teamcity\diff_tools.py", line 32, in _patched_equals
    old(self, first, second, msg)
  File "D:\Program Files\Python\Python38-32\lib\unittest\case.py", line 912, in assertEqual
    assertion_func(first, second, msg=msg)
  File "D:\Program Files\Python\Python38-32\lib\unittest\case.py", line 905, in _baseAssertEqual
    raise self.failureException(msg)
AssertionError: 1 != 2

During handling of the above exception, another exception occurred:

Traceback (most recent call last):
  File "D:\python\pythonProject\api_testing\testcases\test_recharge_new.py", line 68, in test_recharge
    self.assertEqual(expected['code'], res['code'])
  File "D:\Program Files\JetBrains\PyCharm Community Edition 2020.2\plugins\python-ce\helpers\pycharm\teamcity\diff_tools.py", line 38, in _patched_equals
    raise error
teamcity.diff_tools.EqualsAssertionError:  :: 1 != 2
2021-07-01 16:24:09,824 -- [test_recharge_new.py-->line:76] - ERROR: 用例---充值金额-3位小数---执行未通过
2021-07-01 16:24:09,825 -- [test_recharge_new.py-->line:77] - DEBUG: 预期结果：{'code': 2, 'msg': '金额小数超过两位'}
2021-07-01 16:24:09,829 -- [test_recharge_new.py-->line:78] - DEBUG: 实际结果：{'code': 2, 'msg': '余额小数超过两位', 'data': None, 'copyright': 'Copyright 柠檬班 © 2017-2020 湖南省零檬信息技术有限公司 All Rights Reserved'}
2021-07-01 16:24:09,830 -- [test_recharge_new.py-->line:79] - ERROR:  :: 金额小数超过两位 != 余额小数超过两位
Traceback (most recent call last):
  File "D:\Program Files\JetBrains\PyCharm Community Edition 2020.2\plugins\python-ce\helpers\pycharm\teamcity\diff_tools.py", line 32, in _patched_equals
    old(self, first, second, msg)
  File "D:\Program Files\Python\Python38-32\lib\unittest\case.py", line 912, in assertEqual
    assertion_func(first, second, msg=msg)
  File "D:\Program Files\Python\Python38-32\lib\unittest\case.py", line 1292, in assertMultiLineEqual
    self.fail(self._formatMessage(msg, standardMsg))
  File "D:\Program Files\Python\Python38-32\lib\unittest\case.py", line 753, in fail
    raise self.failureException(msg)
AssertionError: '金额小数超过两位' != '余额小数超过两位'
- 金额小数超过两位
? ^
+ 余额小数超过两位
? ^


During handling of the above exception, another exception occurred:

Traceback (most recent call last):
  File "D:\python\pythonProject\api_testing\testcases\test_recharge_new.py", line 69, in test_recharge
    self.assertEqual(expected['msg'], res['msg'])
  File "D:\Program Files\JetBrains\PyCharm Community Edition 2020.2\plugins\python-ce\helpers\pycharm\teamcity\diff_tools.py", line 38, in _patched_equals
    raise error
teamcity.diff_tools.EqualsAssertionError:  :: 金额小数超过两位 != 余额小数超过两位
2021-07-01 16:24:10,741 -- [test_recharge_new.py-->line:76] - ERROR: 用例---充值金额-大于50万---执行未通过
2021-07-01 16:24:10,742 -- [test_recharge_new.py-->line:77] - DEBUG: 预期结果：{'code': 2, 'msg': '金额必须大于0并且小于或者等于500000'}
2021-07-01 16:24:10,742 -- [test_recharge_new.py-->line:78] - DEBUG: 实际结果：{'code': 2, 'msg': '余额必须大于0并且小于或者等于500000', 'data': None, 'copyright': 'Copyright 柠檬班 © 2017-2020 湖南省零檬信息技术有限公司 All Rights Reserved'}
2021-07-01 16:24:10,743 -- [test_recharge_new.py-->line:79] - ERROR:  :: 金额必须大于0并且小于或者等于500000 != 余额必须大于0并且小于或者等于500000
Traceback (most recent call last):
  File "D:\Program Files\JetBrains\PyCharm Community Edition 2020.2\plugins\python-ce\helpers\pycharm\teamcity\diff_tools.py", line 32, in _patched_equals
    old(self, first, second, msg)
  File "D:\Program Files\Python\Python38-32\lib\unittest\case.py", line 912, in assertEqual
    assertion_func(first, second, msg=msg)
  File "D:\Program Files\Python\Python38-32\lib\unittest\case.py", line 1292, in assertMultiLineEqual
    self.fail(self._formatMessage(msg, standardMsg))
  File "D:\Program Files\Python\Python38-32\lib\unittest\case.py", line 753, in fail
    raise self.failureException(msg)
AssertionError: '金额必须大于0并且小于或者等于500000' != '余额必须大于0并且小于或者等于500000'
- 金额必须大于0并且小于或者等于500000
? ^
+ 余额必须大于0并且小于或者等于500000
? ^


During handling of the above exception, another exception occurred:

Traceback (most recent call last):
  File "D:\python\pythonProject\api_testing\testcases\test_recharge_new.py", line 69, in test_recharge
    self.assertEqual(expected['msg'], res['msg'])
  File "D:\Program Files\JetBrains\PyCharm Community Edition 2020.2\plugins\python-ce\helpers\pycharm\teamcity\diff_tools.py", line 38, in _patched_equals
    raise error
teamcity.diff_tools.EqualsAssertionError:  :: 金额必须大于0并且小于或者等于500000 != 余额必须大于0并且小于或者等于500000
2021-07-01 17:09:49,548 -- [recharge.py-->line:66] - ERROR: 测试用例--充值成功-1位小数执行未通过--
2021-07-01 17:09:50,406 -- [recharge.py-->line:66] - ERROR: 测试用例--充值成功-2位小数执行未通过--
2021-07-01 17:09:53,402 -- [recharge.py-->line:66] - ERROR: 测试用例--会员id为字符串执行未通过--
2021-07-01 17:09:54,835 -- [recharge.py-->line:66] - ERROR: 测试用例--充值金额为0执行未通过--
2021-07-01 17:09:56,286 -- [recharge.py-->line:66] - ERROR: 测试用例--充值金额为空执行未通过--
2021-07-01 17:09:56,956 -- [recharge.py-->line:66] - ERROR: 测试用例--充值金额-3位小数执行未通过--
2021-07-01 17:09:57,644 -- [recharge.py-->line:66] - ERROR: 测试用例--充值金额-大于50万执行未通过--
2021-07-01 17:18:03,996 -- [recharge.py-->line:66] - ERROR: 测试用例--充值成功-1位小数执行未通过--
2021-07-01 17:18:05,442 -- [recharge.py-->line:66] - ERROR: 测试用例--充值成功-2位小数执行未通过--
2021-07-01 17:18:09,385 -- [recharge.py-->line:66] - ERROR: 测试用例--会员id为字符串执行未通过--
2021-07-01 17:18:11,611 -- [recharge.py-->line:66] - ERROR: 测试用例--充值金额为0执行未通过--
2021-07-01 17:18:13,956 -- [recharge.py-->line:66] - ERROR: 测试用例--充值金额为空执行未通过--
2021-07-01 17:18:15,064 -- [recharge.py-->line:66] - ERROR: 测试用例--充值金额-3位小数执行未通过--
2021-07-01 17:18:16,192 -- [recharge.py-->line:66] - ERROR: 测试用例--充值金额-大于50万执行未通过--
2021-07-01 17:20:29,109 -- [test_recharge_new.py-->line:76] - ERROR: 用例---会员id为字符串---执行未通过
2021-07-01 17:20:29,110 -- [test_recharge_new.py-->line:77] - DEBUG: 预期结果：{'code': 2, 'msg': '数字格式化异常'}
2021-07-01 17:20:29,111 -- [test_recharge_new.py-->line:78] - DEBUG: 实际结果：{'code': 0, 'msg': 'OK', 'data': {'id': 1362, 'leave_amount': 2009601.28, 'mobile_phone': '15538098212', 'reg_name': '柚柚7', 'reg_time': '2021-07-01 16:23:11.0', 'type': 1}, 'copyright': 'Copyright 柠檬班 © 2017-2020 湖南省零檬信息技术有限公司 All Rights Reserved'}
2021-07-01 17:20:29,111 -- [test_recharge_new.py-->line:79] - ERROR:  :: 2 != 0
Traceback (most recent call last):
  File "D:\Program Files\JetBrains\PyCharm Community Edition 2020.2\plugins\python-ce\helpers\pycharm\teamcity\diff_tools.py", line 32, in _patched_equals
    old(self, first, second, msg)
  File "D:\Program Files\Python\Python38-32\lib\unittest\case.py", line 912, in assertEqual
    assertion_func(first, second, msg=msg)
  File "D:\Program Files\Python\Python38-32\lib\unittest\case.py", line 905, in _baseAssertEqual
    raise self.failureException(msg)
AssertionError: 2 != 0

During handling of the above exception, another exception occurred:

Traceback (most recent call last):
  File "D:\python\pythonProject\api_testing\testcases\test_recharge_new.py", line 68, in test_recharge
    self.assertEqual(expected['code'], res['code'])
  File "D:\Program Files\JetBrains\PyCharm Community Edition 2020.2\plugins\python-ce\helpers\pycharm\teamcity\diff_tools.py", line 38, in _patched_equals
    raise error
teamcity.diff_tools.EqualsAssertionError:  :: 2 != 0
2021-07-01 17:20:31,251 -- [test_recharge_new.py-->line:76] - ERROR: 用例---充值金额为0---执行未通过
2021-07-01 17:20:31,252 -- [test_recharge_new.py-->line:77] - DEBUG: 预期结果：{'code': 2, 'msg': '金额必须大于0并且小于或者等于500000'}
2021-07-01 17:20:31,252 -- [test_recharge_new.py-->line:78] - DEBUG: 实际结果：{'code': 0, 'msg': 'OK', 'data': {'id': 1362, 'leave_amount': 2009601.28, 'mobile_phone': '15538098212', 'reg_name': '柚柚7', 'reg_time': '2021-07-01 16:23:11.0', 'type': 1}, 'copyright': 'Copyright 柠檬班 © 2017-2020 湖南省零檬信息技术有限公司 All Rights Reserved'}
2021-07-01 17:20:31,253 -- [test_recharge_new.py-->line:79] - ERROR:  :: 2 != 0
Traceback (most recent call last):
  File "D:\Program Files\JetBrains\PyCharm Community Edition 2020.2\plugins\python-ce\helpers\pycharm\teamcity\diff_tools.py", line 32, in _patched_equals
    old(self, first, second, msg)
  File "D:\Program Files\Python\Python38-32\lib\unittest\case.py", line 912, in assertEqual
    assertion_func(first, second, msg=msg)
  File "D:\Program Files\Python\Python38-32\lib\unittest\case.py", line 905, in _baseAssertEqual
    raise self.failureException(msg)
AssertionError: 2 != 0

During handling of the above exception, another exception occurred:

Traceback (most recent call last):
  File "D:\python\pythonProject\api_testing\testcases\test_recharge_new.py", line 68, in test_recharge
    self.assertEqual(expected['code'], res['code'])
  File "D:\Program Files\JetBrains\PyCharm Community Edition 2020.2\plugins\python-ce\helpers\pycharm\teamcity\diff_tools.py", line 38, in _patched_equals
    raise error
teamcity.diff_tools.EqualsAssertionError:  :: 2 != 0
2021-07-01 17:20:33,237 -- [test_recharge_new.py-->line:76] - ERROR: 用例---充值金额为空---执行未通过
2021-07-01 17:20:33,238 -- [test_recharge_new.py-->line:77] - DEBUG: 预期结果：{'code': 1, 'msg': '充值金额为空'}
2021-07-01 17:20:33,239 -- [test_recharge_new.py-->line:78] - DEBUG: 实际结果：{'code': 2, 'msg': '余额必须为数值型', 'data': None, 'copyright': 'Copyright 柠檬班 © 2017-2020 湖南省零檬信息技术有限公司 All Rights Reserved'}
2021-07-01 17:20:33,239 -- [test_recharge_new.py-->line:79] - ERROR:  :: 1 != 2
Traceback (most recent call last):
  File "D:\Program Files\JetBrains\PyCharm Community Edition 2020.2\plugins\python-ce\helpers\pycharm\teamcity\diff_tools.py", line 32, in _patched_equals
    old(self, first, second, msg)
  File "D:\Program Files\Python\Python38-32\lib\unittest\case.py", line 912, in assertEqual
    assertion_func(first, second, msg=msg)
  File "D:\Program Files\Python\Python38-32\lib\unittest\case.py", line 905, in _baseAssertEqual
    raise self.failureException(msg)
AssertionError: 1 != 2

During handling of the above exception, another exception occurred:

Traceback (most recent call last):
  File "D:\python\pythonProject\api_testing\testcases\test_recharge_new.py", line 68, in test_recharge
    self.assertEqual(expected['code'], res['code'])
  File "D:\Program Files\JetBrains\PyCharm Community Edition 2020.2\plugins\python-ce\helpers\pycharm\teamcity\diff_tools.py", line 38, in _patched_equals
    raise error
teamcity.diff_tools.EqualsAssertionError:  :: 1 != 2
2021-07-01 17:20:34,239 -- [test_recharge_new.py-->line:76] - ERROR: 用例---充值金额-3位小数---执行未通过
2021-07-01 17:20:34,239 -- [test_recharge_new.py-->line:77] - DEBUG: 预期结果：{'code': 2, 'msg': '金额小数超过两位'}
2021-07-01 17:20:34,240 -- [test_recharge_new.py-->line:78] - DEBUG: 实际结果：{'code': 2, 'msg': '余额小数超过两位', 'data': None, 'copyright': 'Copyright 柠檬班 © 2017-2020 湖南省零檬信息技术有限公司 All Rights Reserved'}
2021-07-01 17:20:34,241 -- [test_recharge_new.py-->line:79] - ERROR:  :: 金额小数超过两位 != 余额小数超过两位
Traceback (most recent call last):
  File "D:\Program Files\JetBrains\PyCharm Community Edition 2020.2\plugins\python-ce\helpers\pycharm\teamcity\diff_tools.py", line 32, in _patched_equals
    old(self, first, second, msg)
  File "D:\Program Files\Python\Python38-32\lib\unittest\case.py", line 912, in assertEqual
    assertion_func(first, second, msg=msg)
  File "D:\Program Files\Python\Python38-32\lib\unittest\case.py", line 1292, in assertMultiLineEqual
    self.fail(self._formatMessage(msg, standardMsg))
  File "D:\Program Files\Python\Python38-32\lib\unittest\case.py", line 753, in fail
    raise self.failureException(msg)
AssertionError: '金额小数超过两位' != '余额小数超过两位'
- 金额小数超过两位
? ^
+ 余额小数超过两位
? ^


During handling of the above exception, another exception occurred:

Traceback (most recent call last):
  File "D:\python\pythonProject\api_testing\testcases\test_recharge_new.py", line 69, in test_recharge
    self.assertEqual(expected['msg'], res['msg'])
  File "D:\Program Files\JetBrains\PyCharm Community Edition 2020.2\plugins\python-ce\helpers\pycharm\teamcity\diff_tools.py", line 38, in _patched_equals
    raise error
teamcity.diff_tools.EqualsAssertionError:  :: 金额小数超过两位 != 余额小数超过两位
2021-07-01 17:20:35,289 -- [test_recharge_new.py-->line:76] - ERROR: 用例---充值金额-大于50万---执行未通过
2021-07-01 17:20:35,290 -- [test_recharge_new.py-->line:77] - DEBUG: 预期结果：{'code': 2, 'msg': '金额必须大于0并且小于或者等于500000'}
2021-07-01 17:20:35,291 -- [test_recharge_new.py-->line:78] - DEBUG: 实际结果：{'code': 2, 'msg': '余额必须大于0并且小于或者等于500000', 'data': None, 'copyright': 'Copyright 柠檬班 © 2017-2020 湖南省零檬信息技术有限公司 All Rights Reserved'}
2021-07-01 17:20:35,292 -- [test_recharge_new.py-->line:79] - ERROR:  :: 金额必须大于0并且小于或者等于500000 != 余额必须大于0并且小于或者等于500000
Traceback (most recent call last):
  File "D:\Program Files\JetBrains\PyCharm Community Edition 2020.2\plugins\python-ce\helpers\pycharm\teamcity\diff_tools.py", line 32, in _patched_equals
    old(self, first, second, msg)
  File "D:\Program Files\Python\Python38-32\lib\unittest\case.py", line 912, in assertEqual
    assertion_func(first, second, msg=msg)
  File "D:\Program Files\Python\Python38-32\lib\unittest\case.py", line 1292, in assertMultiLineEqual
    self.fail(self._formatMessage(msg, standardMsg))
  File "D:\Program Files\Python\Python38-32\lib\unittest\case.py", line 753, in fail
    raise self.failureException(msg)
AssertionError: '金额必须大于0并且小于或者等于500000' != '余额必须大于0并且小于或者等于500000'
- 金额必须大于0并且小于或者等于500000
? ^
+ 余额必须大于0并且小于或者等于500000
? ^


During handling of the above exception, another exception occurred:

Traceback (most recent call last):
  File "D:\python\pythonProject\api_testing\testcases\test_recharge_new.py", line 69, in test_recharge
    self.assertEqual(expected['msg'], res['msg'])
  File "D:\Program Files\JetBrains\PyCharm Community Edition 2020.2\plugins\python-ce\helpers\pycharm\teamcity\diff_tools.py", line 38, in _patched_equals
    raise error
teamcity.diff_tools.EqualsAssertionError:  :: 金额必须大于0并且小于或者等于500000 != 余额必须大于0并且小于或者等于500000
2021-07-07 14:09:40,117 -- [run_tests.py-->line:10] - INFO: 开始执行测试用例......
2021-07-07 14:09:50,619 -- [run_tests.py-->line:26] - INFO: 测试用例执行完毕！
2021-07-07 15:11:06,136 -- [run_tests.py-->line:11] - INFO: 开始执行测试用例......
2021-07-07 15:11:15,153 -- [run_tests.py-->line:28] - INFO: 测试用例执行完毕！
2021-07-07 15:15:36,233 -- [run_tests.py-->line:11] - INFO: 开始执行测试用例......
2021-07-07 15:16:08,976 -- [test_login.py-->line:51] - ERROR: 用例--登录成功--执行未通过
2021-07-07 15:16:10,066 -- [test_login.py-->line:54] - INFO: 用例--手机号为空--执行通过
2021-07-07 15:16:11,164 -- [test_login.py-->line:54] - INFO: 用例--密码为空--执行通过
2021-07-07 15:16:12,600 -- [test_login.py-->line:54] - INFO: 用例--手机号未注册--执行通过
2021-07-07 15:16:14,316 -- [test_login.py-->line:54] - INFO: 用例--密码错误--执行通过
2021-07-07 15:16:15,473 -- [test_login.py-->line:54] - INFO: 用例--手机号格式错误--执行通过
2021-07-07 15:16:25,726 -- [test_recharge_new.py-->line:76] - ERROR: 用例---会员id为字符串---执行未通过
2021-07-07 15:16:25,727 -- [test_recharge_new.py-->line:77] - DEBUG: 预期结果：{'code': 2, 'msg': '数字格式化异常'}
2021-07-07 15:16:25,728 -- [test_recharge_new.py-->line:78] - DEBUG: 实际结果：{'code': 0, 'msg': 'OK', 'data': {'id': 1362, 'leave_amount': 2512001.6, 'mobile_phone': '15538098212', 'reg_name': '柚柚7', 'reg_time': '2021-07-01 16:23:11.0', 'type': 1}, 'copyright': 'Copyright 柠檬班 © 2017-2020 湖南省零檬信息技术有限公司 All Rights Reserved'}
2021-07-07 15:16:25,729 -- [test_recharge_new.py-->line:79] - ERROR: 2 != 0
Traceback (most recent call last):
  File "D:\python\pythonProject\api_testing\testcases\test_recharge_new.py", line 68, in test_recharge
    self.assertEqual(expected['code'], res['code'])
  File "D:\Program Files\Python\Python38-32\lib\unittest\case.py", line 912, in assertEqual
    assertion_func(first, second, msg=msg)
  File "D:\Program Files\Python\Python38-32\lib\unittest\case.py", line 905, in _baseAssertEqual
    raise self.failureException(msg)
AssertionError: 2 != 0
2021-07-07 15:16:28,369 -- [test_recharge_new.py-->line:76] - ERROR: 用例---充值金额为0---执行未通过
2021-07-07 15:16:28,370 -- [test_recharge_new.py-->line:77] - DEBUG: 预期结果：{'code': 2, 'msg': '金额必须大于0并且小于或者等于500000'}
2021-07-07 15:16:28,370 -- [test_recharge_new.py-->line:78] - DEBUG: 实际结果：{'code': 0, 'msg': 'OK', 'data': {'id': 1362, 'leave_amount': 2512001.6, 'mobile_phone': '15538098212', 'reg_name': '柚柚7', 'reg_time': '2021-07-01 16:23:11.0', 'type': 1}, 'copyright': 'Copyright 柠檬班 © 2017-2020 湖南省零檬信息技术有限公司 All Rights Reserved'}
2021-07-07 15:16:28,371 -- [test_recharge_new.py-->line:79] - ERROR: 2 != 0
Traceback (most recent call last):
  File "D:\python\pythonProject\api_testing\testcases\test_recharge_new.py", line 68, in test_recharge
    self.assertEqual(expected['code'], res['code'])
  File "D:\Program Files\Python\Python38-32\lib\unittest\case.py", line 912, in assertEqual
    assertion_func(first, second, msg=msg)
  File "D:\Program Files\Python\Python38-32\lib\unittest\case.py", line 905, in _baseAssertEqual
    raise self.failureException(msg)
AssertionError: 2 != 0
2021-07-07 15:16:31,459 -- [test_recharge_new.py-->line:76] - ERROR: 用例---充值金额为空---执行未通过
2021-07-07 15:16:31,460 -- [test_recharge_new.py-->line:77] - DEBUG: 预期结果：{'code': 1, 'msg': '充值金额为空'}
2021-07-07 15:16:31,461 -- [test_recharge_new.py-->line:78] - DEBUG: 实际结果：{'code': 2, 'msg': '余额必须为数值型', 'data': None, 'copyright': 'Copyright 柠檬班 © 2017-2020 湖南省零檬信息技术有限公司 All Rights Reserved'}
2021-07-07 15:16:31,462 -- [test_recharge_new.py-->line:79] - ERROR: 1 != 2
Traceback (most recent call last):
  File "D:\python\pythonProject\api_testing\testcases\test_recharge_new.py", line 68, in test_recharge
    self.assertEqual(expected['code'], res['code'])
  File "D:\Program Files\Python\Python38-32\lib\unittest\case.py", line 912, in assertEqual
    assertion_func(first, second, msg=msg)
  File "D:\Program Files\Python\Python38-32\lib\unittest\case.py", line 905, in _baseAssertEqual
    raise self.failureException(msg)
AssertionError: 1 != 2
2021-07-07 15:16:32,512 -- [test_recharge_new.py-->line:76] - ERROR: 用例---充值金额-3位小数---执行未通过
2021-07-07 15:16:32,513 -- [test_recharge_new.py-->line:77] - DEBUG: 预期结果：{'code': 2, 'msg': '金额小数超过两位'}
2021-07-07 15:16:32,513 -- [test_recharge_new.py-->line:78] - DEBUG: 实际结果：{'code': 2, 'msg': '余额小数超过两位', 'data': None, 'copyright': 'Copyright 柠檬班 © 2017-2020 湖南省零檬信息技术有限公司 All Rights Reserved'}
2021-07-07 15:16:32,514 -- [test_recharge_new.py-->line:79] - ERROR: '金额小数超过两位' != '余额小数超过两位'
- 金额小数超过两位
? ^
+ 余额小数超过两位
? ^
Traceback (most recent call last):
  File "D:\python\pythonProject\api_testing\testcases\test_recharge_new.py", line 69, in test_recharge
    self.assertEqual(expected['msg'], res['msg'])
  File "D:\Program Files\Python\Python38-32\lib\unittest\case.py", line 912, in assertEqual
    assertion_func(first, second, msg=msg)
  File "D:\Program Files\Python\Python38-32\lib\unittest\case.py", line 1292, in assertMultiLineEqual
    self.fail(self._formatMessage(msg, standardMsg))
  File "D:\Program Files\Python\Python38-32\lib\unittest\case.py", line 753, in fail
    raise self.failureException(msg)
AssertionError: '金额小数超过两位' != '余额小数超过两位'
- 金额小数超过两位
? ^
+ 余额小数超过两位
? ^

2021-07-07 15:16:33,831 -- [test_recharge_new.py-->line:76] - ERROR: 用例---充值金额-大于50万---执行未通过
2021-07-07 15:16:33,833 -- [test_recharge_new.py-->line:77] - DEBUG: 预期结果：{'code': 2, 'msg': '金额必须大于0并且小于或者等于500000'}
2021-07-07 15:16:33,833 -- [test_recharge_new.py-->line:78] - DEBUG: 实际结果：{'code': 2, 'msg': '余额必须大于0并且小于或者等于500000', 'data': None, 'copyright': 'Copyright 柠檬班 © 2017-2020 湖南省零檬信息技术有限公司 All Rights Reserved'}
2021-07-07 15:16:33,834 -- [test_recharge_new.py-->line:79] - ERROR: '金额必须大于0并且小于或者等于500000' != '余额必须大于0并且小于或者等于500000'
- 金额必须大于0并且小于或者等于500000
? ^
+ 余额必须大于0并且小于或者等于500000
? ^
Traceback (most recent call last):
  File "D:\python\pythonProject\api_testing\testcases\test_recharge_new.py", line 69, in test_recharge
    self.assertEqual(expected['msg'], res['msg'])
  File "D:\Program Files\Python\Python38-32\lib\unittest\case.py", line 912, in assertEqual
    assertion_func(first, second, msg=msg)
  File "D:\Program Files\Python\Python38-32\lib\unittest\case.py", line 1292, in assertMultiLineEqual
    self.fail(self._formatMessage(msg, standardMsg))
  File "D:\Program Files\Python\Python38-32\lib\unittest\case.py", line 753, in fail
    raise self.failureException(msg)
AssertionError: '金额必须大于0并且小于或者等于500000' != '余额必须大于0并且小于或者等于500000'
- 金额必须大于0并且小于或者等于500000
? ^
+ 余额必须大于0并且小于或者等于500000
? ^

2021-07-07 15:16:36,750 -- [test_register_new.py-->line:49] - INFO: 用例--注册成功-带注册名--执行通过
2021-07-07 15:16:38,206 -- [test_register_new.py-->line:49] - INFO: 用例--成功-不带用户名--执行通过
2021-07-07 15:16:40,316 -- [test_register_new.py-->line:49] - INFO: 用例--不输入手机号--执行通过
2021-07-07 15:16:41,704 -- [test_register_new.py-->line:49] - INFO: 用例--手机号长度10位--执行通过
2021-07-07 15:16:43,023 -- [test_register_new.py-->line:49] - INFO: 用例--手机号长度12位--执行通过
2021-07-07 15:16:44,645 -- [test_register_new.py-->line:49] - INFO: 用例--手机号含有非法字符--执行通过
2021-07-07 15:16:46,258 -- [test_register_new.py-->line:49] - INFO: 用例--已注册过的手机号--执行通过
2021-07-07 15:16:47,578 -- [test_register_new.py-->line:49] - INFO: 用例--密码7位--执行通过
2021-07-07 15:16:49,254 -- [test_register_new.py-->line:49] - INFO: 用例--密码17位--执行通过
2021-07-07 15:16:50,879 -- [test_register_new.py-->line:49] - INFO: 用例--不输入密码--执行通过
2021-07-07 15:16:52,459 -- [test_register_new.py-->line:49] - INFO: 用例--注册名11位--执行通过
2021-07-07 15:16:54,213 -- [test_register_new.py-->line:49] - INFO: 用例--类型输入非0，1内容--执行通过
2021-07-07 15:16:55,692 -- [test_register_new.py-->line:49] - INFO: 用例--不输入类型--执行通过
2021-07-07 15:17:07,584 -- [test_withdraw_money.py-->line:66] - ERROR: 测试用例--会员id为字符串执行未通过--
2021-07-07 15:17:07,586 -- [test_withdraw_money.py-->line:67] - ERROR: 2 != 0
Traceback (most recent call last):
  File "D:\python\pythonProject\api_testing\testcases\test_withdraw_money.py", line 58, in test_withdraw_money
    self.assertEqual(expected['code'], res['code'])
  File "D:\Program Files\Python\Python38-32\lib\unittest\case.py", line 912, in assertEqual
    assertion_func(first, second, msg=msg)
  File "D:\Program Files\Python\Python38-32\lib\unittest\case.py", line 905, in _baseAssertEqual
    raise self.failureException(msg)
AssertionError: 2 != 0
2021-07-07 15:17:14,111 -- [test_withdraw_money.py-->line:66] - ERROR: 测试用例--提现金额为0执行未通过--
2021-07-07 15:17:14,112 -- [test_withdraw_money.py-->line:67] - ERROR: 2 != 0
Traceback (most recent call last):
  File "D:\python\pythonProject\api_testing\testcases\test_withdraw_money.py", line 58, in test_withdraw_money
    self.assertEqual(expected['code'], res['code'])
  File "D:\Program Files\Python\Python38-32\lib\unittest\case.py", line 912, in assertEqual
    assertion_func(first, second, msg=msg)
  File "D:\Program Files\Python\Python38-32\lib\unittest\case.py", line 905, in _baseAssertEqual
    raise self.failureException(msg)
AssertionError: 2 != 0
2021-07-07 15:17:15,555 -- [test_withdraw_money.py-->line:66] - ERROR: 测试用例--提现金额为负数执行未通过--
2021-07-07 15:17:15,556 -- [test_withdraw_money.py-->line:67] - ERROR: '余额必须大于0并且小于或者等于500000' != '余额必须大于0并且小于或者等于5000000'
- 余额必须大于0并且小于或者等于500000
+ 余额必须大于0并且小于或者等于5000000
?                      +
Traceback (most recent call last):
  File "D:\python\pythonProject\api_testing\testcases\test_withdraw_money.py", line 59, in test_withdraw_money
    self.assertEqual(expected['msg'], res['msg'])
  File "D:\Program Files\Python\Python38-32\lib\unittest\case.py", line 912, in assertEqual
    assertion_func(first, second, msg=msg)
  File "D:\Program Files\Python\Python38-32\lib\unittest\case.py", line 1292, in assertMultiLineEqual
    self.fail(self._formatMessage(msg, standardMsg))
  File "D:\Program Files\Python\Python38-32\lib\unittest\case.py", line 753, in fail
    raise self.failureException(msg)
AssertionError: '余额必须大于0并且小于或者等于500000' != '余额必须大于0并且小于或者等于5000000'
- 余额必须大于0并且小于或者等于500000
+ 余额必须大于0并且小于或者等于5000000
?                      +

2021-07-07 15:17:20,251 -- [test_withdraw_money.py-->line:66] - ERROR: 测试用例--提现金额-大于50万执行未通过--
2021-07-07 15:17:20,252 -- [test_withdraw_money.py-->line:67] - ERROR: '余额必须大于0并且小于或者等于500000' != '余额必须大于0并且小于或者等于5000000'
- 余额必须大于0并且小于或者等于500000
+ 余额必须大于0并且小于或者等于5000000
?                      +
Traceback (most recent call last):
  File "D:\python\pythonProject\api_testing\testcases\test_withdraw_money.py", line 59, in test_withdraw_money
    self.assertEqual(expected['msg'], res['msg'])
  File "D:\Program Files\Python\Python38-32\lib\unittest\case.py", line 912, in assertEqual
    assertion_func(first, second, msg=msg)
  File "D:\Program Files\Python\Python38-32\lib\unittest\case.py", line 1292, in assertMultiLineEqual
    self.fail(self._formatMessage(msg, standardMsg))
  File "D:\Program Files\Python\Python38-32\lib\unittest\case.py", line 753, in fail
    raise self.failureException(msg)
AssertionError: '余额必须大于0并且小于或者等于500000' != '余额必须大于0并且小于或者等于5000000'
- 余额必须大于0并且小于或者等于500000
+ 余额必须大于0并且小于或者等于5000000
?                      +

2021-07-07 15:17:23,462 -- [run_tests.py-->line:28] - INFO: 测试用例执行完毕！
2021-07-07 15:48:16,578 -- [run_tests.py-->line:11] - INFO: 开始执行测试用例......
2021-07-07 15:48:40,196 -- [test_login.py-->line:51] - ERROR: 用例--登录成功--执行未通过
2021-07-07 15:48:41,162 -- [test_login.py-->line:54] - INFO: 用例--手机号为空--执行通过
2021-07-07 15:48:42,058 -- [test_login.py-->line:54] - INFO: 用例--密码为空--执行通过
2021-07-07 15:48:43,059 -- [test_login.py-->line:54] - INFO: 用例--手机号未注册--执行通过
2021-07-07 15:48:44,125 -- [test_login.py-->line:54] - INFO: 用例--密码错误--执行通过
2021-07-07 15:48:45,132 -- [test_login.py-->line:54] - INFO: 用例--手机号格式错误--执行通过
2021-07-07 15:48:53,321 -- [test_recharge_new.py-->line:76] - ERROR: 用例---会员id为字符串---执行未通过
2021-07-07 15:48:53,322 -- [test_recharge_new.py-->line:77] - DEBUG: 预期结果：{'code': 2, 'msg': '数字格式化异常'}
2021-07-07 15:48:53,323 -- [test_recharge_new.py-->line:78] - DEBUG: 实际结果：{'code': 0, 'msg': 'OK', 'data': {'id': 1362, 'leave_amount': 2512001.6, 'mobile_phone': '15538098212', 'reg_name': '柚柚7', 'reg_time': '2021-07-01 16:23:11.0', 'type': 1}, 'copyright': 'Copyright 柠檬班 © 2017-2020 湖南省零檬信息技术有限公司 All Rights Reserved'}
2021-07-07 15:48:53,323 -- [test_recharge_new.py-->line:79] - ERROR: 2 != 0
Traceback (most recent call last):
  File "D:\python\pythonProject\api_testing\testcases\test_recharge_new.py", line 68, in test_recharge
    self.assertEqual(expected['code'], res['code'])
  File "D:\Program Files\Python\Python38-32\lib\unittest\case.py", line 912, in assertEqual
    assertion_func(first, second, msg=msg)
  File "D:\Program Files\Python\Python38-32\lib\unittest\case.py", line 905, in _baseAssertEqual
    raise self.failureException(msg)
AssertionError: 2 != 0
2021-07-07 15:48:55,518 -- [test_recharge_new.py-->line:76] - ERROR: 用例---充值金额为0---执行未通过
2021-07-07 15:48:55,519 -- [test_recharge_new.py-->line:77] - DEBUG: 预期结果：{'code': 2, 'msg': '金额必须大于0并且小于或者等于500000'}
2021-07-07 15:48:55,519 -- [test_recharge_new.py-->line:78] - DEBUG: 实际结果：{'code': 0, 'msg': 'OK', 'data': {'id': 1362, 'leave_amount': 2512001.6, 'mobile_phone': '15538098212', 'reg_name': '柚柚7', 'reg_time': '2021-07-01 16:23:11.0', 'type': 1}, 'copyright': 'Copyright 柠檬班 © 2017-2020 湖南省零檬信息技术有限公司 All Rights Reserved'}
2021-07-07 15:48:55,520 -- [test_recharge_new.py-->line:79] - ERROR: 2 != 0
Traceback (most recent call last):
  File "D:\python\pythonProject\api_testing\testcases\test_recharge_new.py", line 68, in test_recharge
    self.assertEqual(expected['code'], res['code'])
  File "D:\Program Files\Python\Python38-32\lib\unittest\case.py", line 912, in assertEqual
    assertion_func(first, second, msg=msg)
  File "D:\Program Files\Python\Python38-32\lib\unittest\case.py", line 905, in _baseAssertEqual
    raise self.failureException(msg)
AssertionError: 2 != 0
2021-07-07 15:48:57,835 -- [test_recharge_new.py-->line:76] - ERROR: 用例---充值金额为空---执行未通过
2021-07-07 15:48:57,836 -- [test_recharge_new.py-->line:77] - DEBUG: 预期结果：{'code': 1, 'msg': '充值金额为空'}
2021-07-07 15:48:57,837 -- [test_recharge_new.py-->line:78] - DEBUG: 实际结果：{'code': 2, 'msg': '余额必须为数值型', 'data': None, 'copyright': 'Copyright 柠檬班 © 2017-2020 湖南省零檬信息技术有限公司 All Rights Reserved'}
2021-07-07 15:48:57,837 -- [test_recharge_new.py-->line:79] - ERROR: 1 != 2
Traceback (most recent call last):
  File "D:\python\pythonProject\api_testing\testcases\test_recharge_new.py", line 68, in test_recharge
    self.assertEqual(expected['code'], res['code'])
  File "D:\Program Files\Python\Python38-32\lib\unittest\case.py", line 912, in assertEqual
    assertion_func(first, second, msg=msg)
  File "D:\Program Files\Python\Python38-32\lib\unittest\case.py", line 905, in _baseAssertEqual
    raise self.failureException(msg)
AssertionError: 1 != 2
2021-07-07 15:48:58,785 -- [test_recharge_new.py-->line:76] - ERROR: 用例---充值金额-3位小数---执行未通过
2021-07-07 15:48:58,786 -- [test_recharge_new.py-->line:77] - DEBUG: 预期结果：{'code': 2, 'msg': '金额小数超过两位'}
2021-07-07 15:48:58,786 -- [test_recharge_new.py-->line:78] - DEBUG: 实际结果：{'code': 2, 'msg': '余额小数超过两位', 'data': None, 'copyright': 'Copyright 柠檬班 © 2017-2020 湖南省零檬信息技术有限公司 All Rights Reserved'}
2021-07-07 15:48:58,787 -- [test_recharge_new.py-->line:79] - ERROR: '金额小数超过两位' != '余额小数超过两位'
- 金额小数超过两位
? ^
+ 余额小数超过两位
? ^
Traceback (most recent call last):
  File "D:\python\pythonProject\api_testing\testcases\test_recharge_new.py", line 69, in test_recharge
    self.assertEqual(expected['msg'], res['msg'])
  File "D:\Program Files\Python\Python38-32\lib\unittest\case.py", line 912, in assertEqual
    assertion_func(first, second, msg=msg)
  File "D:\Program Files\Python\Python38-32\lib\unittest\case.py", line 1292, in assertMultiLineEqual
    self.fail(self._formatMessage(msg, standardMsg))
  File "D:\Program Files\Python\Python38-32\lib\unittest\case.py", line 753, in fail
    raise self.failureException(msg)
AssertionError: '金额小数超过两位' != '余额小数超过两位'
- 金额小数超过两位
? ^
+ 余额小数超过两位
? ^

2021-07-07 15:48:59,813 -- [test_recharge_new.py-->line:76] - ERROR: 用例---充值金额-大于50万---执行未通过
2021-07-07 15:48:59,814 -- [test_recharge_new.py-->line:77] - DEBUG: 预期结果：{'code': 2, 'msg': '金额必须大于0并且小于或者等于500000'}
2021-07-07 15:48:59,815 -- [test_recharge_new.py-->line:78] - DEBUG: 实际结果：{'code': 2, 'msg': '余额必须大于0并且小于或者等于500000', 'data': None, 'copyright': 'Copyright 柠檬班 © 2017-2020 湖南省零檬信息技术有限公司 All Rights Reserved'}
2021-07-07 15:48:59,816 -- [test_recharge_new.py-->line:79] - ERROR: '金额必须大于0并且小于或者等于500000' != '余额必须大于0并且小于或者等于500000'
- 金额必须大于0并且小于或者等于500000
? ^
+ 余额必须大于0并且小于或者等于500000
? ^
Traceback (most recent call last):
  File "D:\python\pythonProject\api_testing\testcases\test_recharge_new.py", line 69, in test_recharge
    self.assertEqual(expected['msg'], res['msg'])
  File "D:\Program Files\Python\Python38-32\lib\unittest\case.py", line 912, in assertEqual
    assertion_func(first, second, msg=msg)
  File "D:\Program Files\Python\Python38-32\lib\unittest\case.py", line 1292, in assertMultiLineEqual
    self.fail(self._formatMessage(msg, standardMsg))
  File "D:\Program Files\Python\Python38-32\lib\unittest\case.py", line 753, in fail
    raise self.failureException(msg)
AssertionError: '金额必须大于0并且小于或者等于500000' != '余额必须大于0并且小于或者等于500000'
- 金额必须大于0并且小于或者等于500000
? ^
+ 余额必须大于0并且小于或者等于500000
? ^

2021-07-07 15:49:01,994 -- [test_register_new.py-->line:49] - INFO: 用例--注册成功-带注册名--执行通过
2021-07-07 15:49:03,091 -- [test_register_new.py-->line:49] - INFO: 用例--成功-不带用户名--执行通过
2021-07-07 15:49:04,163 -- [test_register_new.py-->line:49] - INFO: 用例--不输入手机号--执行通过
2021-07-07 15:49:05,167 -- [test_register_new.py-->line:49] - INFO: 用例--手机号长度10位--执行通过
2021-07-07 15:49:06,173 -- [test_register_new.py-->line:49] - INFO: 用例--手机号长度12位--执行通过
2021-07-07 15:49:07,165 -- [test_register_new.py-->line:49] - INFO: 用例--手机号含有非法字符--执行通过
2021-07-07 15:49:08,843 -- [test_register_new.py-->line:49] - INFO: 用例--已注册过的手机号--执行通过
2021-07-07 15:49:10,014 -- [test_register_new.py-->line:49] - INFO: 用例--密码7位--执行通过
2021-07-07 15:49:11,033 -- [test_register_new.py-->line:49] - INFO: 用例--密码17位--执行通过
2021-07-07 15:49:12,027 -- [test_register_new.py-->line:49] - INFO: 用例--不输入密码--执行通过
2021-07-07 15:49:13,149 -- [test_register_new.py-->line:49] - INFO: 用例--注册名11位--执行通过
2021-07-07 15:49:14,145 -- [test_register_new.py-->line:49] - INFO: 用例--类型输入非0，1内容--执行通过
2021-07-07 15:49:15,158 -- [test_register_new.py-->line:49] - INFO: 用例--不输入类型--执行通过
2021-07-07 15:49:25,512 -- [test_withdraw_money.py-->line:66] - ERROR: 测试用例--会员id为字符串执行未通过--
2021-07-07 15:49:25,512 -- [test_withdraw_money.py-->line:67] - ERROR: 2 != 0
Traceback (most recent call last):
  File "D:\python\pythonProject\api_testing\testcases\test_withdraw_money.py", line 58, in test_withdraw_money
    self.assertEqual(expected['code'], res['code'])
  File "D:\Program Files\Python\Python38-32\lib\unittest\case.py", line 912, in assertEqual
    assertion_func(first, second, msg=msg)
  File "D:\Program Files\Python\Python38-32\lib\unittest\case.py", line 905, in _baseAssertEqual
    raise self.failureException(msg)
AssertionError: 2 != 0
2021-07-07 15:49:28,270 -- [test_withdraw_money.py-->line:66] - ERROR: 测试用例--提现金额为0执行未通过--
2021-07-07 15:49:28,271 -- [test_withdraw_money.py-->line:67] - ERROR: 2 != 0
Traceback (most recent call last):
  File "D:\python\pythonProject\api_testing\testcases\test_withdraw_money.py", line 58, in test_withdraw_money
    self.assertEqual(expected['code'], res['code'])
  File "D:\Program Files\Python\Python38-32\lib\unittest\case.py", line 912, in assertEqual
    assertion_func(first, second, msg=msg)
  File "D:\Program Files\Python\Python38-32\lib\unittest\case.py", line 905, in _baseAssertEqual
    raise self.failureException(msg)
AssertionError: 2 != 0
2021-07-07 15:49:29,692 -- [test_withdraw_money.py-->line:66] - ERROR: 测试用例--提现金额为负数执行未通过--
2021-07-07 15:49:29,693 -- [test_withdraw_money.py-->line:67] - ERROR: '余额必须大于0并且小于或者等于500000' != '余额必须大于0并且小于或者等于5000000'
- 余额必须大于0并且小于或者等于500000
+ 余额必须大于0并且小于或者等于5000000
?                      +
Traceback (most recent call last):
  File "D:\python\pythonProject\api_testing\testcases\test_withdraw_money.py", line 59, in test_withdraw_money
    self.assertEqual(expected['msg'], res['msg'])
  File "D:\Program Files\Python\Python38-32\lib\unittest\case.py", line 912, in assertEqual
    assertion_func(first, second, msg=msg)
  File "D:\Program Files\Python\Python38-32\lib\unittest\case.py", line 1292, in assertMultiLineEqual
    self.fail(self._formatMessage(msg, standardMsg))
  File "D:\Program Files\Python\Python38-32\lib\unittest\case.py", line 753, in fail
    raise self.failureException(msg)
AssertionError: '余额必须大于0并且小于或者等于500000' != '余额必须大于0并且小于或者等于5000000'
- 余额必须大于0并且小于或者等于500000
+ 余额必须大于0并且小于或者等于5000000
?                      +

2021-07-07 15:49:33,405 -- [test_withdraw_money.py-->line:66] - ERROR: 测试用例--提现金额-大于50万执行未通过--
2021-07-07 15:49:33,406 -- [test_withdraw_money.py-->line:67] - ERROR: '余额必须大于0并且小于或者等于500000' != '余额必须大于0并且小于或者等于5000000'
- 余额必须大于0并且小于或者等于500000
+ 余额必须大于0并且小于或者等于5000000
?                      +
Traceback (most recent call last):
  File "D:\python\pythonProject\api_testing\testcases\test_withdraw_money.py", line 59, in test_withdraw_money
    self.assertEqual(expected['msg'], res['msg'])
  File "D:\Program Files\Python\Python38-32\lib\unittest\case.py", line 912, in assertEqual
    assertion_func(first, second, msg=msg)
  File "D:\Program Files\Python\Python38-32\lib\unittest\case.py", line 1292, in assertMultiLineEqual
    self.fail(self._formatMessage(msg, standardMsg))
  File "D:\Program Files\Python\Python38-32\lib\unittest\case.py", line 753, in fail
    raise self.failureException(msg)
AssertionError: '余额必须大于0并且小于或者等于500000' != '余额必须大于0并且小于或者等于5000000'
- 余额必须大于0并且小于或者等于500000
+ 余额必须大于0并且小于或者等于5000000
?                      +

2021-07-07 15:49:35,666 -- [run_tests.py-->line:28] - INFO: 测试用例执行完毕！
2021-07-07 17:19:06,993 -- [run_tests.py-->line:10] - INFO: 开始执行测试用例......
2021-07-07 17:19:32,475 -- [test_login.py-->line:51] - ERROR: 用例--登录成功--执行未通过
2021-07-07 17:19:33,462 -- [test_login.py-->line:54] - INFO: 用例--手机号为空--执行通过
2021-07-07 17:19:34,394 -- [test_login.py-->line:54] - INFO: 用例--密码为空--执行通过
2021-07-07 17:19:35,390 -- [test_login.py-->line:54] - INFO: 用例--手机号未注册--执行通过
2021-07-07 17:19:36,349 -- [test_login.py-->line:54] - INFO: 用例--密码错误--执行通过
2021-07-07 17:19:37,279 -- [test_login.py-->line:54] - INFO: 用例--手机号格式错误--执行通过
2021-07-07 17:19:44,931 -- [test_recharge_new.py-->line:76] - ERROR: 用例---会员id为字符串---执行未通过
2021-07-07 17:19:44,932 -- [test_recharge_new.py-->line:77] - DEBUG: 预期结果：{'code': 2, 'msg': '数字格式化异常'}
2021-07-07 17:19:44,932 -- [test_recharge_new.py-->line:78] - DEBUG: 实际结果：{'code': 0, 'msg': 'OK', 'data': {'id': 1362, 'leave_amount': 2512001.6, 'mobile_phone': '15538098212', 'reg_name': '柚柚7', 'reg_time': '2021-07-01 16:23:11.0', 'type': 1}, 'copyright': 'Copyright 柠檬班 © 2017-2020 湖南省零檬信息技术有限公司 All Rights Reserved'}
2021-07-07 17:19:44,933 -- [test_recharge_new.py-->line:79] - ERROR: 2 != 0
Traceback (most recent call last):
  File "D:\python\pythonProject\api_testing\testcases\test_recharge_new.py", line 68, in test_recharge
    self.assertEqual(expected['code'], res['code'])
  File "D:\Program Files\Python\Python38-32\lib\unittest\case.py", line 912, in assertEqual
    assertion_func(first, second, msg=msg)
  File "D:\Program Files\Python\Python38-32\lib\unittest\case.py", line 905, in _baseAssertEqual
    raise self.failureException(msg)
AssertionError: 2 != 0
2021-07-07 17:19:47,375 -- [test_recharge_new.py-->line:76] - ERROR: 用例---充值金额为0---执行未通过
2021-07-07 17:19:47,376 -- [test_recharge_new.py-->line:77] - DEBUG: 预期结果：{'code': 2, 'msg': '金额必须大于0并且小于或者等于500000'}
2021-07-07 17:19:47,377 -- [test_recharge_new.py-->line:78] - DEBUG: 实际结果：{'code': 0, 'msg': 'OK', 'data': {'id': 1362, 'leave_amount': 2512001.6, 'mobile_phone': '15538098212', 'reg_name': '柚柚7', 'reg_time': '2021-07-01 16:23:11.0', 'type': 1}, 'copyright': 'Copyright 柠檬班 © 2017-2020 湖南省零檬信息技术有限公司 All Rights Reserved'}
2021-07-07 17:19:47,377 -- [test_recharge_new.py-->line:79] - ERROR: 2 != 0
Traceback (most recent call last):
  File "D:\python\pythonProject\api_testing\testcases\test_recharge_new.py", line 68, in test_recharge
    self.assertEqual(expected['code'], res['code'])
  File "D:\Program Files\Python\Python38-32\lib\unittest\case.py", line 912, in assertEqual
    assertion_func(first, second, msg=msg)
  File "D:\Program Files\Python\Python38-32\lib\unittest\case.py", line 905, in _baseAssertEqual
    raise self.failureException(msg)
AssertionError: 2 != 0
2021-07-07 17:19:49,417 -- [test_recharge_new.py-->line:76] - ERROR: 用例---充值金额为空---执行未通过
2021-07-07 17:19:49,418 -- [test_recharge_new.py-->line:77] - DEBUG: 预期结果：{'code': 1, 'msg': '充值金额为空'}
2021-07-07 17:19:49,418 -- [test_recharge_new.py-->line:78] - DEBUG: 实际结果：{'code': 2, 'msg': '余额必须为数值型', 'data': None, 'copyright': 'Copyright 柠檬班 © 2017-2020 湖南省零檬信息技术有限公司 All Rights Reserved'}
2021-07-07 17:19:49,419 -- [test_recharge_new.py-->line:79] - ERROR: 1 != 2
Traceback (most recent call last):
  File "D:\python\pythonProject\api_testing\testcases\test_recharge_new.py", line 68, in test_recharge
    self.assertEqual(expected['code'], res['code'])
  File "D:\Program Files\Python\Python38-32\lib\unittest\case.py", line 912, in assertEqual
    assertion_func(first, second, msg=msg)
  File "D:\Program Files\Python\Python38-32\lib\unittest\case.py", line 905, in _baseAssertEqual
    raise self.failureException(msg)
AssertionError: 1 != 2
2021-07-07 17:19:50,576 -- [test_recharge_new.py-->line:76] - ERROR: 用例---充值金额-3位小数---执行未通过
2021-07-07 17:19:50,577 -- [test_recharge_new.py-->line:77] - DEBUG: 预期结果：{'code': 2, 'msg': '金额小数超过两位'}
2021-07-07 17:19:50,578 -- [test_recharge_new.py-->line:78] - DEBUG: 实际结果：{'code': 2, 'msg': '余额小数超过两位', 'data': None, 'copyright': 'Copyright 柠檬班 © 2017-2020 湖南省零檬信息技术有限公司 All Rights Reserved'}
2021-07-07 17:19:50,579 -- [test_recharge_new.py-->line:79] - ERROR: '金额小数超过两位' != '余额小数超过两位'
- 金额小数超过两位
? ^
+ 余额小数超过两位
? ^
Traceback (most recent call last):
  File "D:\python\pythonProject\api_testing\testcases\test_recharge_new.py", line 69, in test_recharge
    self.assertEqual(expected['msg'], res['msg'])
  File "D:\Program Files\Python\Python38-32\lib\unittest\case.py", line 912, in assertEqual
    assertion_func(first, second, msg=msg)
  File "D:\Program Files\Python\Python38-32\lib\unittest\case.py", line 1292, in assertMultiLineEqual
    self.fail(self._formatMessage(msg, standardMsg))
  File "D:\Program Files\Python\Python38-32\lib\unittest\case.py", line 753, in fail
    raise self.failureException(msg)
AssertionError: '金额小数超过两位' != '余额小数超过两位'
- 金额小数超过两位
? ^
+ 余额小数超过两位
? ^

2021-07-07 17:19:51,858 -- [test_recharge_new.py-->line:76] - ERROR: 用例---充值金额-大于50万---执行未通过
2021-07-07 17:19:51,859 -- [test_recharge_new.py-->line:77] - DEBUG: 预期结果：{'code': 2, 'msg': '金额必须大于0并且小于或者等于500000'}
2021-07-07 17:19:51,860 -- [test_recharge_new.py-->line:78] - DEBUG: 实际结果：{'code': 2, 'msg': '余额必须大于0并且小于或者等于500000', 'data': None, 'copyright': 'Copyright 柠檬班 © 2017-2020 湖南省零檬信息技术有限公司 All Rights Reserved'}
2021-07-07 17:19:51,860 -- [test_recharge_new.py-->line:79] - ERROR: '金额必须大于0并且小于或者等于500000' != '余额必须大于0并且小于或者等于500000'
- 金额必须大于0并且小于或者等于500000
? ^
+ 余额必须大于0并且小于或者等于500000
? ^
Traceback (most recent call last):
  File "D:\python\pythonProject\api_testing\testcases\test_recharge_new.py", line 69, in test_recharge
    self.assertEqual(expected['msg'], res['msg'])
  File "D:\Program Files\Python\Python38-32\lib\unittest\case.py", line 912, in assertEqual
    assertion_func(first, second, msg=msg)
  File "D:\Program Files\Python\Python38-32\lib\unittest\case.py", line 1292, in assertMultiLineEqual
    self.fail(self._formatMessage(msg, standardMsg))
  File "D:\Program Files\Python\Python38-32\lib\unittest\case.py", line 753, in fail
    raise self.failureException(msg)
AssertionError: '金额必须大于0并且小于或者等于500000' != '余额必须大于0并且小于或者等于500000'
- 金额必须大于0并且小于或者等于500000
? ^
+ 余额必须大于0并且小于或者等于500000
? ^

2021-07-07 17:19:54,016 -- [test_register_new.py-->line:49] - INFO: 用例--注册成功-带注册名--执行通过
2021-07-07 17:19:55,150 -- [test_register_new.py-->line:49] - INFO: 用例--成功-不带用户名--执行通过
2021-07-07 17:19:56,213 -- [test_register_new.py-->line:49] - INFO: 用例--不输入手机号--执行通过
2021-07-07 17:19:57,239 -- [test_register_new.py-->line:49] - INFO: 用例--手机号长度10位--执行通过
2021-07-07 17:19:58,263 -- [test_register_new.py-->line:49] - INFO: 用例--手机号长度12位--执行通过
2021-07-07 17:19:59,274 -- [test_register_new.py-->line:49] - INFO: 用例--手机号含有非法字符--执行通过
2021-07-07 17:20:00,372 -- [test_register_new.py-->line:49] - INFO: 用例--已注册过的手机号--执行通过
2021-07-07 17:20:01,611 -- [test_register_new.py-->line:49] - INFO: 用例--密码7位--执行通过
2021-07-07 17:20:02,632 -- [test_register_new.py-->line:49] - INFO: 用例--密码17位--执行通过
2021-07-07 17:20:03,653 -- [test_register_new.py-->line:49] - INFO: 用例--不输入密码--执行通过
2021-07-07 17:20:04,646 -- [test_register_new.py-->line:49] - INFO: 用例--注册名11位--执行通过
2021-07-07 17:20:05,645 -- [test_register_new.py-->line:49] - INFO: 用例--类型输入非0，1内容--执行通过
2021-07-07 17:20:06,693 -- [test_register_new.py-->line:49] - INFO: 用例--不输入类型--执行通过
2021-07-07 17:20:15,309 -- [test_withdraw_money.py-->line:66] - ERROR: 测试用例--会员id为字符串执行未通过--
2021-07-07 17:20:15,310 -- [test_withdraw_money.py-->line:67] - ERROR: 2 != 0
Traceback (most recent call last):
  File "D:\python\pythonProject\api_testing\testcases\test_withdraw_money.py", line 58, in test_withdraw_money
    self.assertEqual(expected['code'], res['code'])
  File "D:\Program Files\Python\Python38-32\lib\unittest\case.py", line 912, in assertEqual
    assertion_func(first, second, msg=msg)
  File "D:\Program Files\Python\Python38-32\lib\unittest\case.py", line 905, in _baseAssertEqual
    raise self.failureException(msg)
AssertionError: 2 != 0
2021-07-07 17:20:17,717 -- [test_withdraw_money.py-->line:66] - ERROR: 测试用例--提现金额为0执行未通过--
2021-07-07 17:20:17,718 -- [test_withdraw_money.py-->line:67] - ERROR: 2 != 0
Traceback (most recent call last):
  File "D:\python\pythonProject\api_testing\testcases\test_withdraw_money.py", line 58, in test_withdraw_money
    self.assertEqual(expected['code'], res['code'])
  File "D:\Program Files\Python\Python38-32\lib\unittest\case.py", line 912, in assertEqual
    assertion_func(first, second, msg=msg)
  File "D:\Program Files\Python\Python38-32\lib\unittest\case.py", line 905, in _baseAssertEqual
    raise self.failureException(msg)
AssertionError: 2 != 0
2021-07-07 17:20:18,990 -- [test_withdraw_money.py-->line:66] - ERROR: 测试用例--提现金额为负数执行未通过--
2021-07-07 17:20:18,991 -- [test_withdraw_money.py-->line:67] - ERROR: '余额必须大于0并且小于或者等于500000' != '余额必须大于0并且小于或者等于5000000'
- 余额必须大于0并且小于或者等于500000
+ 余额必须大于0并且小于或者等于5000000
?                      +
Traceback (most recent call last):
  File "D:\python\pythonProject\api_testing\testcases\test_withdraw_money.py", line 59, in test_withdraw_money
    self.assertEqual(expected['msg'], res['msg'])
  File "D:\Program Files\Python\Python38-32\lib\unittest\case.py", line 912, in assertEqual
    assertion_func(first, second, msg=msg)
  File "D:\Program Files\Python\Python38-32\lib\unittest\case.py", line 1292, in assertMultiLineEqual
    self.fail(self._formatMessage(msg, standardMsg))
  File "D:\Program Files\Python\Python38-32\lib\unittest\case.py", line 753, in fail
    raise self.failureException(msg)
AssertionError: '余额必须大于0并且小于或者等于500000' != '余额必须大于0并且小于或者等于5000000'
- 余额必须大于0并且小于或者等于500000
+ 余额必须大于0并且小于或者等于5000000
?                      +

2021-07-07 17:20:22,732 -- [test_withdraw_money.py-->line:66] - ERROR: 测试用例--提现金额-大于50万执行未通过--
2021-07-07 17:20:22,733 -- [test_withdraw_money.py-->line:67] - ERROR: '余额必须大于0并且小于或者等于500000' != '余额必须大于0并且小于或者等于5000000'
- 余额必须大于0并且小于或者等于500000
+ 余额必须大于0并且小于或者等于5000000
?                      +
Traceback (most recent call last):
  File "D:\python\pythonProject\api_testing\testcases\test_withdraw_money.py", line 59, in test_withdraw_money
    self.assertEqual(expected['msg'], res['msg'])
  File "D:\Program Files\Python\Python38-32\lib\unittest\case.py", line 912, in assertEqual
    assertion_func(first, second, msg=msg)
  File "D:\Program Files\Python\Python38-32\lib\unittest\case.py", line 1292, in assertMultiLineEqual
    self.fail(self._formatMessage(msg, standardMsg))
  File "D:\Program Files\Python\Python38-32\lib\unittest\case.py", line 753, in fail
    raise self.failureException(msg)
AssertionError: '余额必须大于0并且小于或者等于500000' != '余额必须大于0并且小于或者等于5000000'
- 余额必须大于0并且小于或者等于500000
+ 余额必须大于0并且小于或者等于5000000
?                      +

2021-07-07 17:20:24,927 -- [run_tests.py-->line:27] - INFO: 测试用例执行完毕！
2021-07-08 13:57:41,946 -- [test_login.py-->line:51] - ERROR: 用例--登录成功--执行未通过
2021-07-08 13:57:43,360 -- [test_login.py-->line:54] - INFO: 用例--手机号为空--执行通过
2021-07-08 13:57:44,359 -- [test_login.py-->line:54] - INFO: 用例--密码为空--执行通过
2021-07-08 13:57:45,378 -- [test_login.py-->line:54] - INFO: 用例--手机号未注册--执行通过
2021-07-08 13:57:46,525 -- [test_login.py-->line:54] - INFO: 用例--密码错误--执行通过
2021-07-08 13:57:47,528 -- [test_login.py-->line:54] - INFO: 用例--手机号格式错误--执行通过
2021-07-21 16:33:33,880 -- [test_login.py-->line:52] - ERROR: 用例--登录成功--执行未通过
2021-07-21 16:33:35,040 -- [test_login.py-->line:55] - INFO: 用例--手机号为空--执行通过
2021-07-21 16:33:36,641 -- [test_login.py-->line:55] - INFO: 用例--密码为空--执行通过
2021-07-21 16:33:37,767 -- [test_login.py-->line:55] - INFO: 用例--手机号未注册--执行通过
2021-07-21 16:33:38,846 -- [test_login.py-->line:55] - INFO: 用例--密码错误--执行通过
2021-07-21 16:33:40,474 -- [test_login.py-->line:55] - INFO: 用例--手机号格式错误--执行通过
